Workbook
Name ATLIST: Calc!$J$2:$J$5
Name LALIST: Language!$B$1:$D$1
Name LFLIST: Calc!$M$2:$M$6
Name LLIST1: Calc!$C$2:$C$7
Name LLIST2: Calc!$D$2:$D$6
Name MFLIST: Calc!$L$2:$L$6
Name NOLIST: Calc!$G$2
Name SSLIST: Calc!$K$2:$K$4
Name TMLIST: Calc!$H$2:$H$4
Name WLIST1: Calc!$E$2:$E$4
Name WLIST2: Calc!$F$2:$F$3
Name WOLIST: Calc!$I$2:$I$5

Sheet PRC import
A2: Import code | B2: Article code | C2: Description | D2: Quantity | E2: Unit | G2: Project reference
A3: 1 | B3: 1 | C3: =List!D236 | D3: 1 | E3: st | G3: Description language | H3: English
A4: =IF(B4="",0,3) | B4: =List!D237
A5: =IF(B5="",0,3) | B5: =List!D238 | G5: Agent name | H5: Bycommute
A6: =IF(B6="",0,3) | B6: =List!D239 | G6: Discount percent | H6: 35
A7: =IF(B7="",0,3) | B7: =List!D240 | G7: Bruto Price | H7: =List!$H$118
A8: =IF(B8="",0,3) | B8: =List!D241 | G8: Discount | H8: =ROUND(-H7*H6/100,2)
A9: =IF(B9="",0,3) | B9: =List!D242 | G9: Netto Price | H9: =H7+H8
A10: =IF(B10="",0,3) | B10: =List!D243 | G10: Valid from | H10: 28 August 2025
A11: =IF(B11="",0,3) | B11: =List!D244 | G11: Valid until | H11: Next version
A12: =IF(B12="",0,3) | B12: =List!D245
A13: 0 | G13: Installation time | H13: =Calc!D69
A14: 0 | B14: Bill of material | G14: DISCLAIMER: Use with caution.
A15: =IF(B15="",0,2) | B15: =List!C119 | C15: =List!D119 | D15: =List!E119 | E15: =List!F119 | G15: Installation time is in labor hours, divide by team size for calendar hours, transport and foundations excluded. Actual installation time may vary significantly based on team experience, site conditions and equipment.
A16: =IF(B16="",0,2) | B16: =List!C120 | C16: =List!D120 | D16: =List!E120 | E16: =List!F120
A17: =IF(B17="",0,2) | B17: =List!C121 | C17: =List!D121 | D17: =List!E121 | E17: =List!F121
A18: =IF(B18="",0,2) | B18: =List!C122 | C18: =List!D122 | D18: =List!E122 | E18: =List!F122
A19: =IF(B19="",0,2) | B19: =List!C123 | C19: =List!D123 | D19: =List!E123 | E19: =List!F123
A20: =IF(B20="",0,2) | B20: =List!C124 | C20: =List!D124 | D20: =List!E124 | E20: =List!F124
A21: =IF(B21="",0,2) | B21: =List!C125 | C21: =List!D125 | D21: =List!E125 | E21: =List!F125
A22: =IF(B22="",0,2) | B22: =List!C126 | C22: =List!D126 | D22: =List!E126 | E22: =List!F126
A23: =IF(B23="",0,2) | B23: =List!C127 | C23: =List!D127 | D23: =List!E127 | E23: =List!F127
A24: =IF(B24="",0,2) | B24: =List!C128 | C24: =List!D128 | D24: =List!E128 | E24: =List!F128
A25: =IF(B25="",0,2) | B25: =List!C129 | C25: =List!D129 | D25: =List!E129 | E25: =List!F129
A26: =IF(B26="",0,2) | B26: =List!C130 | C26: =List!D130 | D26: =List!E130 | E26: =List!F130
A27: =IF(B27="",0,2) | B27: =List!C131 | C27: =List!D131 | D27: =List!E131 | E27: =List!F131
... A131: =IF(B131="",0,2) | B131: =List!C235 | C131: =List!D235 | D131: =List!E235 | E131: =List!F235

Sheet Configure
A1: L W | B1: 5.06 | C1: * | D1: * | E1: * | F1: * | G1: *
A2: 2.03 | B2: =IF(OR(B$1=NOLIST,$A2=NOLIST),"",$A2+0.12&"x"&B$1+0.12&"m") | C2: =IF(OR(C$1=NOLIST,$A2=NOLIST),"",$A2+0.12&"x"&C$1&"m") | D2: =IF(OR(D$1=NOLIST,$A2=NOLIST),"",$A2+0.12&"x"&D$1&"m") | E2: =IF(OR(E$1=NOLIST,$A2=NOLIST),"",$A2+0.12&"x"&E$1&"m") | F2: =IF(OR(F$1=NOLIST,$A2=NOLIST),"",$A2+0.12&"x"&F$1&"m") | G2: =IF(OR(G$1=NOLIST,$A2=NOLIST),"",$A2+0.12&"x"&G$1&"m")
A3: 2.03 | B3: =IF(OR(B$1=NOLIST,$A3=NOLIST),"",$A3&"x"&B$1+0.12&"m") | C3: =IF(OR(C$1=NOLIST,$A3=NOLIST),"",$A3&"x"&C$1&"m") | D3: =IF(OR(D$1=NOLIST,$A3=NOLIST),"",$A3&"x"&D$1&"m") | E3: =IF(OR(E$1=NOLIST,$A3=NOLIST),"",$A3&"x"&E$1&"m") | F3: =IF(OR(F$1=NOLIST,$A3=NOLIST),"",$A3&"x"&F$1&"m") | G3: =IF(OR(G$1=NOLIST,$A3=NOLIST),"",$A3&"x"&G$1&"m")
A4: 2.03 | B4: =IF(OR(B$1=NOLIST,$A4=NOLIST),"",$A4&"x"&B$1+0.12&"m") | C4: =IF(OR(C$1=NOLIST,$A4=NOLIST),"",$A4&"x"&C$1&"m") | D4: =IF(OR(D$1=NOLIST,$A4=NOLIST),"",$A4&"x"&D$1&"m") | E4: =IF(OR(E$1=NOLIST,$A4=NOLIST),"",$A4&"x"&E$1&"m") | F4: =IF(OR(F$1=NOLIST,$A4=NOLIST),"",$A4&"x"&F$1&"m") | G4: =IF(OR(G$1=NOLIST,$A4=NOLIST),"",$A4&"x"&G$1&"m")
A5: 2.03 | B5: =IF(OR(B$1=NOLIST,$A5=NOLIST),"",$A5&"x"&B$1+0.12&"m") | C5: =IF(OR(C$1=NOLIST,$A5=NOLIST),"",$A5&"x"&C$1&"m") | D5: =IF(OR(D$1=NOLIST,$A5=NOLIST),"",$A5&"x"&D$1&"m") | E5: =IF(OR(E$1=NOLIST,$A5=NOLIST),"",$A5&"x"&E$1&"m") | F5: =IF(OR(F$1=NOLIST,$A5=NOLIST),"",$A5&"x"&F$1&"m") | G5: =IF(OR(G$1=NOLIST,$A5=NOLIST),"",$A5&"x"&G$1&"m")
A6: 2.03 | B6: =IF(OR(B$1=NOLIST,$A6=NOLIST),"",$A6&"x"&B$1+0.12&"m") | C6: =IF(OR(C$1=NOLIST,$A6=NOLIST),"",$A6&"x"&C$1&"m") | D6: =IF(OR(D$1=NOLIST,$A6=NOLIST),"",$A6&"x"&D$1&"m") | E6: =IF(OR(E$1=NOLIST,$A6=NOLIST),"",$A6&"x"&E$1&"m") | F6: =IF(OR(F$1=NOLIST,$A6=NOLIST),"",$A6&"x"&F$1&"m") | G6: =IF(OR(G$1=NOLIST,$A6=NOLIST),"",$A6&"x"&G$1&"m")
A7: 2.03 | B7: =IF(OR(B$1=NOLIST,$A7=NOLIST),"",$A7&"x"&B$1+0.12&"m") | C7: =IF(OR(C$1=NOLIST,$A7=NOLIST),"",$A7&"x"&C$1&"m") | D7: =IF(OR(D$1=NOLIST,$A7=NOLIST),"",$A7&"x"&D$1&"m") | E7: =IF(OR(E$1=NOLIST,$A7=NOLIST),"",$A7&"x"&E$1&"m") | F7: =IF(OR(F$1=NOLIST,$A7=NOLIST),"",$A7&"x"&F$1&"m") | G7: =IF(OR(G$1=NOLIST,$A7=NOLIST),"",$A7&"x"&G$1&"m")
A8: * | B8: =IF(OR(B$1=NOLIST,$A8=NOLIST),"",$A8&"x"&B$1+0.12&"m") | C8: =IF(OR(C$1=NOLIST,$A8=NOLIST),"",$A8&"x"&C$1&"m") | D8: =IF(OR(D$1=NOLIST,$A8=NOLIST),"",$A8&"x"&D$1&"m") | E8: =IF(OR(E$1=NOLIST,$A8=NOLIST),"",$A8&"x"&E$1&"m") | F8: =IF(OR(F$1=NOLIST,$A8=NOLIST),"",$A8&"x"&F$1&"m") | G8: =IF(OR(G$1=NOLIST,$A8=NOLIST),"",$A8&"x"&G$1&"m")
A9: * | B9: =IF(OR(B$1=NOLIST,$A9=NOLIST),"",$A9&"x"&B$1+0.12&"m") | C9: =IF(OR(C$1=NOLIST,$A9=NOLIST),"",$A9&"x"&C$1&"m") | D9: =IF(OR(D$1=NOLIST,$A9=NOLIST),"",$A9&"x"&D$1&"m") | E9: =IF(OR(E$1=NOLIST,$A9=NOLIST),"",$A9&"x"&E$1&"m") | F9: =IF(OR(F$1=NOLIST,$A9=NOLIST),"",$A9&"x"&F$1&"m") | G9: =IF(OR(G$1=NOLIST,$A9=NOLIST),"",$A9&"x"&G$1&"m")
A10: * | B10: =IF(OR(B$1=NOLIST,$A10=NOLIST),"",$A10&"x"&B$1+0.12&"m") | C10: =IF(OR(C$1=NOLIST,$A10=NOLIST),"",$A10&"x"&C$1&"m") | D10: =IF(OR(D$1=NOLIST,$A10=NOLIST),"",$A10&"x"&D$1&"m") | E10: =IF(OR(E$1=NOLIST,$A10=NOLIST),"",$A10&"x"&E$1&"m") | F10: =IF(OR(F$1=NOLIST,$A10=NOLIST),"",$A10&"x"&F$1&"m") | G10: =IF(OR(G$1=NOLIST,$A10=NOLIST),"",$A10&"x"&G$1&"m")
A11: * | B11: =IF(OR(B$1=NOLIST,$A11=NOLIST),"",$A11&"x"&B$1+0.12&"m") | C11: =IF(OR(C$1=NOLIST,$A11=NOLIST),"",$A11&"x"&C$1&"m") | D11: =IF(OR(D$1=NOLIST,$A11=NOLIST),"",$A11&"x"&D$1&"m") | E11: =IF(OR(E$1=NOLIST,$A11=NOLIST),"",$A11&"x"&E$1&"m") | F11: =IF(OR(F$1=NOLIST,$A11=NOLIST),"",$A11&"x"&F$1&"m") | G11: =IF(OR(G$1=NOLIST,$A11=NOLIST),"",$A11&"x"&G$1&"m")
A12: * | B12: =IF(OR(B$1=NOLIST,$A12=NOLIST),"",$A12&"x"&B$1+0.12&"m") | C12: =IF(OR(C$1=NOLIST,$A12=NOLIST),"",$A12&"x"&C$1&"m") | D12: =IF(OR(D$1=NOLIST,$A12=NOLIST),"",$A12&"x"&D$1&"m") | E12: =IF(OR(E$1=NOLIST,$A12=NOLIST),"",$A12&"x"&E$1&"m") | F12: =IF(OR(F$1=NOLIST,$A12=NOLIST),"",$A12&"x"&F$1&"m") | G12: =IF(OR(G$1=NOLIST,$A12=NOLIST),"",$A12&"x"&G$1&"m")
A13: * | B13: =IF(OR(B$1=NOLIST,$A13=NOLIST),"",$A13&"x"&B$1+0.12&"m") | C13: =IF(OR(C$1=NOLIST,$A13=NOLIST),"",$A13&"x"&C$1&"m") | D13: =IF(OR(D$1=NOLIST,$A13=NOLIST),"",$A13&"x"&D$1&"m") | E13: =IF(OR(E$1=NOLIST,$A13=NOLIST),"",$A13&"x"&E$1&"m") | F13: =IF(OR(F$1=NOLIST,$A13=NOLIST),"",$A13&"x"&F$1&"m") | G13: =IF(OR(G$1=NOLIST,$A13=NOLIST),"",$A13&"x"&G$1&"m")
F15: Roof dimensions - WxL= | G15: =IF(OR(A2="*",B1="*"),"",Calc!D12)
A16: Treatment | B16: Powder coated | F16: Centre-to-centre dimensions - WxL= | G16: =IF(OR(A2="*",B1="*"),"",Calc!D11)
A17: Version | B17: Standard
E18: =_xlfn.TEXTJOIN(CHAR(10),TRUE,Calc!E85:E103)
A19: Wall material | B19: 2D mesh
A20: Mesh finish | B20: RAV716
A21: Top wall | B21: Yes
A22: Right wall | B22: Yes
A23: Bottom wall | B23: Yes
A24: Left wall | B24: Yes
A25: Remove cladding | B25: No
A27: Entrance type | B27: Segment size | C27: Amount
A28: Single swing gate | B28: 2.03 | C28: 1
A32: Gate hardware kit
A33: Euro cylinder lock
F34: Domino Excel config
A35: Roof edge trim | B35: No | F35: Date | G35: 45896
A36: Chemical anchors | B36: Yes | F36: Version | G36: 2.3-EXP
F37: Author | G37: ST

Sheet Calc
C1: LLIST1 | D1: LLIST2 | E1: WLIST1 | F1: WLIST2 | G1: NOLIST | H1: TMLIST | I1: WOLIST | J1: ATLIST | K1: SSLIST | L1: MFLIST | M1: LFLIST
C2: * | D2: 2.03 | E2: * | F2: 2.03 | G2: * | H2: Galvanized | I2: No wall
C3: 2.03 | D3: 2.53 | E3: 2.03 | F3: 2.53 | H3: Powder coated | I3: 2D mesh | J3: Wall opening | K3: 2.03 | L3: RAL6005 | M3: Euro cylinder lock
C4: 2.53 | D4: 4.06 | E4: 2.53 | H4: Roof edge coated | I4: Thermowood | J4: Single swing gate | K4: 2.53 | L4: RAL7016 | M4: Mechanical code lock
C5: 4.06 | D5: 5.06 | I5: Glass | J5: Double swing gate | L5: RAL9005 | M5: Battery powered code lock
C6: 5.06 | D6: 6.09 | L6: Galvanized | M6: No lock or fittings
C7: 6.09
C9: Width (axis) | D9: =D27*2.03+D28*2.53
C10: Length (axis) | D10: =D30*2.03+D31*2.53+D32*4.06+D33*5.06+D34*6.09
C11: WxL (axis) | D11: =D9&"x"&D10&"m"
C12: WxL (roof) | D12: =D9+0.12&"x"&D10+0.12&"m"
C14: Roof | D14: 0 | E14: Steel = 0 / Polycarbonate = 1
C15: Treatment | D15: =_xlfn.IFNA(MATCH(Configure!B16,TMLIST,0)-1,0) | E15: Galvanized = 0 / Powder coated = 1 / Roof edge coated = 2
C16: Treatment roof edge | D16: {=_xlfn.SWITCH($D$15,0,0,1,1,2,1)} | E16: Galvanized = 0 / Powder coated = 1
C17: Treatment structure | D17: {=_xlfn.SWITCH($D$15,0,0,1,1,2,0)} | E17: Galvanized = 0 / Powder coated = 1
C18: Version | D18: =IF(Configure!B17="PLUS",1,0) | E18: Standard height = 0 / PLUS = 1
C19: LED | D19: 0
C20: Beams | D20: 1
C21: Roof edge trim | D21: =IF(Configure!B35="Yes",1,0)
C22: Chemical anchors | D22: =IF(Configure!B36="Yes",1,0)
C23: Wedge anchors | D23: 0
C24: Sealant | D24: 0
C26: Modules W | D26: =SUM(D27:D28) | E26: WARNING: Overriding D24-D33 will miscalculate braces; update D60-D63 as well.
C27: Modules W2 | D27: =COUNTIF(Configure!A2:A13,2.03)
C28: Modules W2,5 | D28: =COUNTIF(Configure!A2:A13,2.53)
C29: Modules L | D29: =SUM(D30:D34)
C30: Modules L2 | D30: =COUNTIF(Configure!B1:G1,2.03)
C31: Modules L2,5 | D31: =COUNTIF(Configure!B1:G1,2.53)
C32: Modules L4 | D32: =COUNTIF(Configure!B1:G1,4.06)
C33: Modules L5 | D33: =COUNTIF(Configure!B1:G1,5.06)
C34: Modules L6 | D34: =COUNTIF(Configure!B1:G1,6.09)
C35: Modules | D35: =D29*D26
C37: Wall material | D37: =_xlfn.IFNA(MATCH(Configure!B19,WOLIST,0)-1,0) | E37: No wall = 0 / 2D Mesh = 1 / Thermowood = 2 / Glass = 3
C38: 2D Mesh finish | D38: =_xlfn.IFNA(MATCH(Configure!B20,MFLIST,0)-1,0) | E38: No finish = 0 / RAL6005 = 1 / RAL7016 = 2 / RAL9005 = 3 / Galvanized = 4
C39: Top Wall | D39: =IF(Configure!B21="Yes",1,0)
C40: Right Wall | D40: =IF(Configure!B22="Yes",1,0)
C41: Bottom Wall | D41: =IF(Configure!B23="Yes",1,0)
C42: Left Wall | D42: =IF(Configure!B24="Yes",1,0)
C43: Walls 2 | D43: =($D$39+$D$41)*D30+($D$40+$D$42)*D27
C44: Walls 2,5 | D44: =($D$39+$D$41)*D31+($D$40+$D$42)*D28
...

Sheet Fastening
D1: Hexagon head bolt DIN933 - M10X30 | E1: Hexagon head bolt DIN933 - M10X60 | F1: Hexagon head bolt DIN933 - M10X80 | G1: Hexagon head bolt DIN933 - M10X90 | H1: Hexagon head bolt DIN933 - M10X100 | I1: Hexagon head bolt DIN933 - M10X110 | J1: Hexagon head bolt DIN933 - M10X140 | K1: Hexagon nut DIN934 - M10 | L1: Plain washer DIN125-1A - M10 | M1: Thread forming bolt DIN7500D - M10x30 | N1: Nut Cap PE black - M10 | O1: Hexagon socket button head screw ISO 7380-2 - M10x40 | P1: Self-drilling screw neoprene washer DIN7504K - 6,3x25 | Q1: Wood screw Stainless A2 4x35mm | R1: Self-drilling screw with wings 5,5x50mm | S1: Blind rivet Waterproof DIN7337A - 4,8x12,5 | T1: Nylon sleeve PA6 - Ø26/14x6mm | U1: Leafguard Ø50/70mm | V1: Hybrid polymer sealant 400ml - Transparent Proma Bond 334906 | W1: Anchor rod - Zinc plated M12x160-5.8 Würth W-VD-A/S | X1: Chemical anchor capsule M12x95 Würth W-VPZ 12 | Y1: Wedge Anchor Baraco FM753ZN M12/40x139mm | Z1: Hexagon domed cap nut Zinc plated M12 | AA1: Panel Clamp - Uni Double - RAL9005 incl. screw and cap | AB1: Panel Clamp - Uni Single - RAL9005 incl. screw and cap | AC1: Plug 107VS VM 12 - RAL7035 OBO 2029517 | AD1: Conduit coupler 20mm - Straight RAL7035 - Helia 34623 | AE1: Conduit end cap 20mm - RAL7035 Helia 34523 | AF1: Conduit clip M6 19-22 - RAL7035 OBO 2140233 | AG1: Self-drilling screw DIN7504M-H - 4,2x25
C2: QTY | D2: 15.02.02.0124 | E2: 15.02.02.0131 | F2: 15.02.02.0135 | G2: 15.02.02.0136 | H2: 15.02.02.0137 | I2: 15.02.02.0138 | J2: 15.02.02.0142 | K2: 15.03.01.0009 | L2: 15.08.03.0006 | M2: 15.02.11.0141 | N2: 19.02.02.0006 | O2: 15.02.05.0066 | P2: 15.06.02.0050 | Q2: 16.04.03.0124 | R2: 14.09.01.0002 | S2: 17.04.01.0058 | T2: 19.04.00.0001 | U2: 27.05.01.0001 | V2: 34.03.02.0034 | W2: 18.01.18.0001 | X2: 18.03.03.0001 | Y2: 18.01.09.0142 | Z2: 15.03.04.0006 | AA2: 20.05.01.0004 | AB2: 20.05.01.0005 | AC2: 30.03.03.0027 | AD2: 30.04.04.0002 | AE2: 30.04.03.0004 | AF2: 30.04.02.0008 | AG2: 15.06.05.0011
A3: 43.09.06.0001 | B3: Domino - Mof A - Galvanized | C3: =_xlfn.XLOOKUP(A3,List!$C$2:$C$89,List!$E$2:$E$89,"",0) | D3: 4 | H3: 1 | K3: 5 | L3: 10 | M3: 2 | U3: 1 | V3: =0.25*Calc!$D$24
A4: 43.09.06.0006 | B4: Domino - Mof A - Powder Coated | C4: =_xlfn.XLOOKUP(A4,List!$C$2:$C$89,List!$E$2:$E$89,"",0) | D4: 4 | H4: 1 | K4: 5 | L4: 10 | M4: 2 | N4: 12 | U4: 1 | V4: =0.25*Calc!$D$24
A5: 43.09.06.0002 | B5: Domino - Mof B - Galvanized | C5: =_xlfn.XLOOKUP(A5,List!$C$2:$C$89,List!$E$2:$E$89,"",0) | D5: 4 | H5: 1 | K5: 5 | L5: 10 | M5: 2 | V5: =0.25*Calc!$D$24
A6: 43.09.06.0007 | B6: Domino - Mof B - Powder Coated | C6: =_xlfn.XLOOKUP(A6,List!$C$2:$C$89,List!$E$2:$E$89,"",0) | D6: 4 | H6: 1 | K6: 5 | L6: 10 | M6: 2 | N6: 12 | V6: =0.25*Calc!$D$24
A7: 43.09.06.0003 | B7: Domino - Mof C - Galvanized | C7: =_xlfn.XLOOKUP(A7,List!$C$2:$C$89,List!$E$2:$E$89,"",0) | D7: 6 | H7: 1 | K7: 7 | L7: 14 | M7: 2 | U7: 1 | V7: =0.5*Calc!$D$24
A8: 43.09.06.0008 | B8: Domino - Mof C - Powder Coated | C8: =_xlfn.XLOOKUP(A8,List!$C$2:$C$89,List!$E$2:$E$89,"",0) | D8: 6 | H8: 1 | K8: 7 | L8: 14 | M8: 2 | N8: 16 | U8: 1 | V8: =0.5*Calc!$D$24
A9: 43.09.06.0005 | B9: Domino - Mof D - Galvanized | C9: =_xlfn.XLOOKUP(A9,List!$C$2:$C$89,List!$E$2:$E$89,"",0) | D9: 4 | H9: 1 | K9: 5 | L9: 10 | M9: 2 | V9: =0.25*Calc!$D$24
A10: 43.09.06.0010 | B10: Domino - Mof D - Powder Coated | C10: =_xlfn.XLOOKUP(A10,List!$C$2:$C$89,List!$E$2:$E$89,"",0) | D10: 4 | H10: 1 | K10: 5 | L10: 10 | M10: 2 | N10: 12 | V10: =0.25*Calc!$D$24
A11: 43.09.06.0004 | B11: Domino - Mof W - Galvanized | C11: =_xlfn.XLOOKUP(A11,List!$C$2:$C$89,List!$E$2:$E$89,"",0) | D11: 1 | H11: 1 | K11: 2 | L11: 4 | M11: 2
A12: 43.09.06.0009 | B12: Domino - Mof W - Powder Coated | C12: =_xlfn.XLOOKUP(A12,List!$C$2:$C$89,List!$E$2:$E$89,"",0) | D12: 1 | H12: 1 | K12: 2 | L12: 4 | M12: 2 | N12: 6
A13: 43.03.10.0002 | B13: Domino - Foot - 70x4 - L605 - Galvanized | C13: =_xlfn.XLOOKUP(A13,List!$C$2:$C$89,List!$E$2:$E$89,"",0) | M13: 4 | W13: =4*Calc!$D$22 | X13: =4*Calc!$D$22 | Y13: =4*Calc!$D$23 | Z13: =IF((Calc!$D$23+Calc!$D$22)>0,4,0)
A14: 43.03.10.0001 | B14: Domino - Foot - 70x4 - L605 - Outflow - Galvanized | C14: =_xlfn.XLOOKUP(A14,List!$C$2:$C$89,List!$E$2:$E$89,"",0) | M14: 4 | W14: =4*Calc!$D$22 | X14: =4*Calc!$D$22 | Y14: =4*Calc!$D$23 | Z14: =IF((Calc!$D$23+Calc!$D$22)>0,4,0)
A15: 43.03.10.0004 | B15: Domino - Foot - 70x4 - L605 - Outflow - Powder Coated | C15: =_xlfn.XLOOKUP(A15,List!$C$2:$C$89,List!$E$2:$E$89,"",0) | M15: 4 | N15: 4 | W15: =4*Calc!$D$22 | X15: =4*Calc!$D$22 | Y15: =4*Calc!$D$23 | Z15: =IF((Calc!$D$23+Calc!$D$22)>0,4,0)
A16: 43.03.10.0005 | B16: Domino - Foot - 70x4 - L605 - Powder Coated | C16: =_xlfn.XLOOKUP(A16,List!$C$2:$C$89,List!$E$2:$E$89,"",0) | M16: 4 | N16: 4 | W16: =4*Calc!$D$22 | X16: =4*Calc!$D$22 | Y16: =4*Calc!$D$23 | Z16: =IF((Calc!$D$23+Calc!$D$22)>0,4,0)
A17: 43.03.10.0003 | B17: Domino - Foot 70x50x3 - L600 - Galvanized | C17: =_xlfn.XLOOKUP(A17,List!$C$2:$C$89,List!$E$2:$E$89,"",0) | D17: 1 | K17: 1 | L17: 2 | M17: 4 | W17: =2*Calc!$D$22 | X17: =2*Calc!$D$22 | Y17: =2*Calc!$D$23 | Z17: =IF((Calc!$D$23+Calc!$D$22)>0,2,0)
A18: 43.03.10.0006 | B18: Domino - Foot 70x50x3 - L600 - Powder coated | C18: =_xlfn.XLOOKUP(A18,List!$C$2:$C$89,List!$E$2:$E$89,"",0) | D18: 1 | K18: 1 | L18: 2 | M18: 4 | N18: 6 | W18: =2*Calc!$D$22 | X18: =2*Calc!$D$22 | Y18: =2*Calc!$D$23 | Z18: =IF((Calc!$D$23+Calc!$D$22)>0,2,0)
A19: 37.60.06.0168 | B19: Domino - U-Profile - 80x50x3 - L1890 - 3Ø13 - Galvanized | C19: =_xlfn.XLOOKUP(A19,List!$C$2:$C$89,List!$E$2:$E$89,"",0) | D19: 3 | K19: 3 | L19: 6
A20: 43.17.06.0004 | B20: Domino - U-Profile - 80x50x3 - L1890 - 3Ø13 - Powder Coated | C20: =_xlfn.XLOOKUP(A20,List!$C$2:$C$89,List!$E$2:$E$89,"",0) | D20: 3 | K20: 3 | L20: 6 | N20: 6
A21: 37.60.06.0169 | B21: Domino - U-Profile - 80x50x3 - L2390 - 3Ø13 - Galvanized | C21: =_xlfn.XLOOKUP(A21,List!$C$2:$C$89,List!$E$2:$E$89,"",0) | D21: 3 | K21: 3 | L21: 6
A22: 43.17.06.0005 | B22: Domino - U-Profile - 80x50x3 - L2390 - 3Ø13 - Powder Coated | C22: =_xlfn.XLOOKUP(A22,List!$C$2:$C$89,List!$E$2:$E$89,"",0) | D22: 3 | K22: 3 | L22: 6 | N22: 6
A23: 37.60.06.0017 | B23: Domino - U-Profile - 80x50x3 - L3920 - 4Ø13 - Galvanized | C23: =_xlfn.XLOOKUP(A23,List!$C$2:$C$89,List!$E$2:$E$89,"",0) | D23: 4 | K23: 4 | L23: 8
A24: 43.17.06.0001 | B24: Domino - U-Profile - 80x50x3 - L3920 - 4Ø13 - Powder Coated | C24: =_xlfn.XLOOKUP(A24,List!$C$2:$C$89,List!$E$2:$E$89,"",0) | D24: 4 | K24: 4 | L24: 8 | N24: 8
A25: 37.60.06.0018 | B25: Domino - U-Profile - 80x50x3 - L4920 - 4Ø13 - Galvanized | C25: =_xlfn.XLOOKUP(A25,List!$C$2:$C$89,List!$E$2:$E$89,"",0) | D25: 4 | K25: 4 | L25: 8
A26: 43.17.06.0002 | B26: Domino - U-Profile - 80x50x3 - L4920 - 4Ø13 - Powder Coated | C26: =_xlfn.XLOOKUP(A26,List!$C$2:$C$89,List!$E$2:$E$89,"",0) | D26: 4 | K26: 4 | L26: 8 | N26: 8
A27: 37.60.06.0019 | B27: Domino - U-Profile - 80x50x3 - L5950 - 4Ø13 - Galvanized | C27: =_xlfn.XLOOKUP(A27,List!$C$2:$C$89,List!$E$2:$E$89,"",0) | D27: 4 | K27: 4 | L27: 8
A28: 43.17.06.0003 | B28: Domino - U-Profile - 80x50x3 - L5950 - 4Ø13 - Powder Coated | C28: =_xlfn.XLOOKUP(A28,List!$C$2:$C$89,List!$E$2:$E$89,"",0) | D28: 4 | K28: 4 | L28: 8 | N28: 8
A29: 43.07.18.0001 | B29: Domino - Wall Connector - Galvanized | C29: =_xlfn.XLOOKUP(A29,List!$C$2:$C$89,List!$E$2:$E$89,"",0) | M29: 2
A30: 43.07.18.0004 | B30: Domino - Wall Connector - Powder Coated | C30: =_xlfn.XLOOKUP(A30,List!$C$2:$C$89,List!$E$2:$E$89,"",0) | M30: 2 | N30: 2
A31: 43.32.03.0048 | B31: Domino - Hinge Bracket - Galvanized | C31: =_xlfn.XLOOKUP(A31,List!$C$2:$C$89,List!$E$2:$E$89,"",0) | M31: 2
A32: 43.32.03.0049 | B32: Domino - Hinge Bracket - Powder coated | C32: =_xlfn.XLOOKUP(A32,List!$C$2:$C$89,List!$E$2:$E$89,"",0) | M32: 2 | N32: 2
A33: 43.32.03.0050 | B33: Domino - Hinge L-Profile - Galvanized | C33: =_xlfn.XLOOKUP(A33,List!$C$2:$C$89,List!$E$2:$E$89,"",0) | E33: =IF(Calc!$D$37=1,2,0) | F33: =IF(Calc!$D$37<>1,2,0) | K33: 2 | L33: 4
A34: 43.32.03.0051 | B34: Domino - Hinge L-Profile - Powder coated | C34: =_xlfn.XLOOKUP(A34,List!$C$2:$C$89,List!$E$2:$E$89,"",0) | E34: =IF(Calc!$D$37=1,2,0) | F34: =IF(Calc!$D$37<>1,2,0) | K34: 2 | L34: 4 | N34: 4
A35: 44.02.06.0029 | B35: Domino - Girder - 50x2 - L293mm - 2Ø13 - 2M10 - Galvanized | C35: =_xlfn.XLOOKUP(A35,List!$C$2:$C$89,List!$E$2:$E$89,"",0) | D35: 2 | L35: 2
A36: 44.02.06.0030 | B36: Domino - Girder - 50x2 - L543mm - 2Ø13 - 2M10 - Galvanized | C36: =_xlfn.XLOOKUP(A36,List!$C$2:$C$89,List!$E$2:$E$89,"",0) | D36: 2 | L36: 2
A37: 44.02.06.0031 | B37: Domino - Girder - 50x2 - L293mm - 2Ø13 - 2M10 - Powder coated | C37: =_xlfn.XLOOKUP(A37,List!$C$2:$C$89,List!$E$2:$E$89,"",0) | D37: 2 | L37: 2 | N37: 2
A38: 44.02.06.0032 | B38: Domino - Girder - 50x2 - L543mm - 2Ø13 - 2M10 - Powder coated | C38: =_xlfn.XLOOKUP(A38,List!$C$2:$C$89,List!$E$2:$E$89,"",0) | D38: 2 | L38: 2 | N38: 2
A39: 44.02.06.0005 | B39: Domino - Girder - 50x2 - L1948 - 6Ø13 - 6M10 - Galvanized | C39: =_xlfn.XLOOKUP(A39,List!$C$2:$C$89,List!$E$2:$E$89,"",0) | D39: 2 | L39: 2 | O39: 4
A40: 44.02.06.0009 | B40: Domino - Girder - 50x2 - L1948 - 6Ø13 - 6M10 - Powder Coated | C40: =_xlfn.XLOOKUP(A40,List!$C$2:$C$89,List!$E$2:$E$89,"",0) | D40: 2 | L40: 2 | N40: 2 | O40: 4
...

Sheet List
A1: INDEX2 | B1: INDEX | C1: CODE | D1: DESCR | E1: QTY | F1: UNIT
B2: 1 | C2: =_xlfn.XLOOKUP(B2,Calc!$A$128:$A$545,Calc!$G$128:$G$545,"",0) | D2: =_xlfn.XLOOKUP(B2,Calc!$A$128:$A$545,Calc!$H$128:$H$545,"",0) | E2: =_xlfn.XLOOKUP(B2,Calc!$A$128:$A$545,Calc!$C$128:$C$545,"",0) | F2: =_xlfn.XLOOKUP(C2,Articles!$A$2:$A$232,Articles!$C$2:$C$232,"",0)
B3: 2 | C3: =_xlfn.XLOOKUP(B3,Calc!$A$128:$A$545,Calc!$G$128:$G$545,"",0) | D3: =_xlfn.XLOOKUP(B3,Calc!$A$128:$A$545,Calc!$H$128:$H$545,"",0) | E3: =_xlfn.XLOOKUP(B3,Calc!$A$128:$A$545,Calc!$C$128:$C$545,"",0) | F3: =_xlfn.XLOOKUP(C3,Articles!$A$2:$A$232,Articles!$C$2:$C$232,"",0)
B4: 3 | C4: =_xlfn.XLOOKUP(B4,Calc!$A$128:$A$545,Calc!$G$128:$G$545,"",0) | D4: =_xlfn.XLOOKUP(B4,Calc!$A$128:$A$545,Calc!$H$128:$H$545,"",0) | E4: =_xlfn.XLOOKUP(B4,Calc!$A$128:$A$545,Calc!$C$128:$C$545,"",0) | F4: =_xlfn.XLOOKUP(C4,Articles!$A$2:$A$232,Articles!$C$2:$C$232,"",0)
B5: 4 | C5: =_xlfn.XLOOKUP(B5,Calc!$A$128:$A$545,Calc!$G$128:$G$545,"",0) | D5: =_xlfn.XLOOKUP(B5,Calc!$A$128:$A$545,Calc!$H$128:$H$545,"",0) | E5: =_xlfn.XLOOKUP(B5,Calc!$A$128:$A$545,Calc!$C$128:$C$545,"",0) | F5: =_xlfn.XLOOKUP(C5,Articles!$A$2:$A$232,Articles!$C$2:$C$232,"",0)
B6: 5 | C6: =_xlfn.XLOOKUP(B6,Calc!$A$128:$A$545,Calc!$G$128:$G$545,"",0) | D6: =_xlfn.XLOOKUP(B6,Calc!$A$128:$A$545,Calc!$H$128:$H$545,"",0) | E6: =_xlfn.XLOOKUP(B6,Calc!$A$128:$A$545,Calc!$C$128:$C$545,"",0) | F6: =_xlfn.XLOOKUP(C6,Articles!$A$2:$A$232,Articles!$C$2:$C$232,"",0)
B7: 6 | C7: =_xlfn.XLOOKUP(B7,Calc!$A$128:$A$545,Calc!$G$128:$G$545,"",0) | D7: =_xlfn.XLOOKUP(B7,Calc!$A$128:$A$545,Calc!$H$128:$H$545,"",0) | E7: =_xlfn.XLOOKUP(B7,Calc!$A$128:$A$545,Calc!$C$128:$C$545,"",0) | F7: =_xlfn.XLOOKUP(C7,Articles!$A$2:$A$232,Articles!$C$2:$C$232,"",0)
B8: 7 | C8: =_xlfn.XLOOKUP(B8,Calc!$A$128:$A$545,Calc!$G$128:$G$545,"",0) | D8: =_xlfn.XLOOKUP(B8,Calc!$A$128:$A$545,Calc!$H$128:$H$545,"",0) | E8: =_xlfn.XLOOKUP(B8,Calc!$A$128:$A$545,Calc!$C$128:$C$545,"",0) | F8: =_xlfn.XLOOKUP(C8,Articles!$A$2:$A$232,Articles!$C$2:$C$232,"",0)
B9: 8 | C9: =_xlfn.XLOOKUP(B9,Calc!$A$128:$A$545,Calc!$G$128:$G$545,"",0) | D9: =_xlfn.XLOOKUP(B9,Calc!$A$128:$A$545,Calc!$H$128:$H$545,"",0) | E9: =_xlfn.XLOOKUP(B9,Calc!$A$128:$A$545,Calc!$C$128:$C$545,"",0) | F9: =_xlfn.XLOOKUP(C9,Articles!$A$2:$A$232,Articles!$C$2:$C$232,"",0)
B10: 9 | C10: =_xlfn.XLOOKUP(B10,Calc!$A$128:$A$545,Calc!$G$128:$G$545,"",0) | D10: =_xlfn.XLOOKUP(B10,Calc!$A$128:$A$545,Calc!$H$128:$H$545,"",0) | E10: =_xlfn.XLOOKUP(B10,Calc!$A$128:$A$545,Calc!$C$128:$C$545,"",0) | F10: =_xlfn.XLOOKUP(C10,Articles!$A$2:$A$232,Articles!$C$2:$C$232,"",0)
B11: 10 | C11: =_xlfn.XLOOKUP(B11,Calc!$A$128:$A$545,Calc!$G$128:$G$545,"",0) | D11: =_xlfn.XLOOKUP(B11,Calc!$A$128:$A$545,Calc!$H$128:$H$545,"",0) | E11: =_xlfn.XLOOKUP(B11,Calc!$A$128:$A$545,Calc!$C$128:$C$545,"",0) | F11: =_xlfn.XLOOKUP(C11,Articles!$A$2:$A$232,Articles!$C$2:$C$232,"",0)
B12: 11 | C12: =_xlfn.XLOOKUP(B12,Calc!$A$128:$A$545,Calc!$G$128:$G$545,"",0) | D12: =_xlfn.XLOOKUP(B12,Calc!$A$128:$A$545,Calc!$H$128:$H$545,"",0) | E12: =_xlfn.XLOOKUP(B12,Calc!$A$128:$A$545,Calc!$C$128:$C$545,"",0) | F12: =_xlfn.XLOOKUP(C12,Articles!$A$2:$A$232,Articles!$C$2:$C$232,"",0)
B13: 12 | C13: =_xlfn.XLOOKUP(B13,Calc!$A$128:$A$545,Calc!$G$128:$G$545,"",0) | D13: =_xlfn.XLOOKUP(B13,Calc!$A$128:$A$545,Calc!$H$128:$H$545,"",0) | E13: =_xlfn.XLOOKUP(B13,Calc!$A$128:$A$545,Calc!$C$128:$C$545,"",0) | F13: =_xlfn.XLOOKUP(C13,Articles!$A$2:$A$232,Articles!$C$2:$C$232,"",0)
... B88: 87 | C88: =_xlfn.XLOOKUP(B88,Calc!$A$128:$A$545,Calc!$G$128:$G$545,"",0) | D88: =_xlfn.XLOOKUP(B88,Calc!$A$128:$A$545,Calc!$H$128:$H$545,"",0) | E88: =_xlfn.XLOOKUP(B88,Calc!$A$128:$A$545,Calc!$C$128:$C$545,"",0) | F88: =_xlfn.XLOOKUP(C88,Articles!$A$2:$A$232,Articles!$C$2:$C$232,"",0)
A89: =COUNT(E2:E89) | B89: 88 | C89: =_xlfn.XLOOKUP(B89,Calc!$A$128:$A$545,Calc!$G$128:$G$545,"",0) | D89: =_xlfn.XLOOKUP(B89,Calc!$A$128:$A$545,Calc!$H$128:$H$545,"",0) | E89: =_xlfn.XLOOKUP(B89,Calc!$A$128:$A$545,Calc!$C$128:$C$545,"",0) | F89: =_xlfn.XLOOKUP(C89,Articles!$A$2:$A$232,Articles!$C$2:$C$232,"",0)
A90: =$A$89+B90 | B90: 1 | C90: =_xlfn.XLOOKUP(B90,Fastening!$E$78:$E$107,Fastening!$A$78:$A$107,"",0) | D90: =_xlfn.XLOOKUP(B90,Fastening!$E$78:$E$107,Fastening!$B$78:$B$107,"",0) | E90: {=_xlfn.XLOOKUP(B90,Fastening!$E$78:$E$107,_xlfn.ANCHORARRAY(Fastening!$C$78),"",0)} | F90: =_xlfn.XLOOKUP(C90,Articles!$A$2:$A$232,Articles!$C$2:$C$232,"",0)
A91: =$A$89+B91 | B91: 2 | C91: =_xlfn.XLOOKUP(B91,Fastening!$E$78:$E$107,Fastening!$A$78:$A$107,"",0) | D91: =_xlfn.XLOOKUP(B91,Fastening!$E$78:$E$107,Fastening!$B$78:$B$107,"",0) | E91: {=_xlfn.XLOOKUP(B91,Fastening!$E$78:$E$107,_xlfn.ANCHORARRAY(Fastening!$C$78),"",0)} | F91: =_xlfn.XLOOKUP(C91,Articles!$A$2:$A$232,Articles!$C$2:$C$232,"",0)
A92: =$A$89+B92 | B92: 3 | C92: =_xlfn.XLOOKUP(B92,Fastening!$E$78:$E$107,Fastening!$A$78:$A$107,"",0) | D92: =_xlfn.XLOOKUP(B92,Fastening!$E$78:$E$107,Fastening!$B$78:$B$107,"",0) | E92: {=_xlfn.XLOOKUP(B92,Fastening!$E$78:$E$107,_xlfn.ANCHORARRAY(Fastening!$C$78),"",0)} | F92: =_xlfn.XLOOKUP(C92,Articles!$A$2:$A$232,Articles!$C$2:$C$232,"",0)
A93: =$A$89+B93 | B93: 4 | C93: =_xlfn.XLOOKUP(B93,Fastening!$E$78:$E$107,Fastening!$A$78:$A$107,"",0) | D93: =_xlfn.XLOOKUP(B93,Fastening!$E$78:$E$107,Fastening!$B$78:$B$107,"",0) | E93: {=_xlfn.XLOOKUP(B93,Fastening!$E$78:$E$107,_xlfn.ANCHORARRAY(Fastening!$C$78),"",0)} | F93: =_xlfn.XLOOKUP(C93,Articles!$A$2:$A$232,Articles!$C$2:$C$232,"",0)
A94: =$A$89+B94 | B94: 5 | C94: =_xlfn.XLOOKUP(B94,Fastening!$E$78:$E$107,Fastening!$A$78:$A$107,"",0) | D94: =_xlfn.XLOOKUP(B94,Fastening!$E$78:$E$107,Fastening!$B$78:$B$107,"",0) | E94: {=_xlfn.XLOOKUP(B94,Fastening!$E$78:$E$107,_xlfn.ANCHORARRAY(Fastening!$C$78),"",0)} | F94: =_xlfn.XLOOKUP(C94,Articles!$A$2:$A$232,Articles!$C$2:$C$232,"",0)
A95: =$A$89+B95 | B95: 6 | C95: =_xlfn.XLOOKUP(B95,Fastening!$E$78:$E$107,Fastening!$A$78:$A$107,"",0) | D95: =_xlfn.XLOOKUP(B95,Fastening!$E$78:$E$107,Fastening!$B$78:$B$107,"",0) | E95: {=_xlfn.XLOOKUP(B95,Fastening!$E$78:$E$107,_xlfn.ANCHORARRAY(Fastening!$C$78),"",0)} | F95: =_xlfn.XLOOKUP(C95,Articles!$A$2:$A$232,Articles!$C$2:$C$232,"",0)
A96: =$A$89+B96 | B96: 7 | C96: =_xlfn.XLOOKUP(B96,Fastening!$E$78:$E$107,Fastening!$A$78:$A$107,"",0) | D96: =_xlfn.XLOOKUP(B96,Fastening!$E$78:$E$107,Fastening!$B$78:$B$107,"",0) | E96: {=_xlfn.XLOOKUP(B96,Fastening!$E$78:$E$107,_xlfn.ANCHORARRAY(Fastening!$C$78),"",0)} | F96: =_xlfn.XLOOKUP(C96,Articles!$A$2:$A$232,Articles!$C$2:$C$232,"",0)
A97: =$A$89+B97 | B97: 8 | C97: =_xlfn.XLOOKUP(B97,Fastening!$E$78:$E$107,Fastening!$A$78:$A$107,"",0) | D97: =_xlfn.XLOOKUP(B97,Fastening!$E$78:$E$107,Fastening!$B$78:$B$107,"",0) | E97: {=_xlfn.XLOOKUP(B97,Fastening!$E$78:$E$107,_xlfn.ANCHORARRAY(Fastening!$C$78),"",0)} | F97: =_xlfn.XLOOKUP(C97,Articles!$A$2:$A$232,Articles!$C$2:$C$232,"",0)
A98: =$A$89+B98 | B98: 9 | C98: =_xlfn.XLOOKUP(B98,Fastening!$E$78:$E$107,Fastening!$A$78:$A$107,"",0) | D98: =_xlfn.XLOOKUP(B98,Fastening!$E$78:$E$107,Fastening!$B$78:$B$107,"",0) | E98: {=_xlfn.XLOOKUP(B98,Fastening!$E$78:$E$107,_xlfn.ANCHORARRAY(Fastening!$C$78),"",0)} | F98: =_xlfn.XLOOKUP(C98,Articles!$A$2:$A$232,Articles!$C$2:$C$232,"",0)
A99: =$A$89+B99 | B99: 10 | C99: =_xlfn.XLOOKUP(B99,Fastening!$E$78:$E$107,Fastening!$A$78:$A$107,"",0) | D99: =_xlfn.XLOOKUP(B99,Fastening!$E$78:$E$107,Fastening!$B$78:$B$107,"",0) | E99: {=_xlfn.XLOOKUP(B99,Fastening!$E$78:$E$107,_xlfn.ANCHORARRAY(Fastening!$C$78),"",0)} | F99: =_xlfn.XLOOKUP(C99,Articles!$A$2:$A$232,Articles!$C$2:$C$232,"",0)
A100: =$A$89+B100 | B100: 11 | C100: =_xlfn.XLOOKUP(B100,Fastening!$E$78:$E$107,Fastening!$A$78:$A$107,"",0) | D100: =_xlfn.XLOOKUP(B100,Fastening!$E$78:$E$107,Fastening!$B$78:$B$107,"",0) | E100: {=_xlfn.XLOOKUP(B100,Fastening!$E$78:$E$107,_xlfn.ANCHORARRAY(Fastening!$C$78),"",0)} | F100: =_xlfn.XLOOKUP(C100,Articles!$A$2:$A$232,Articles!$C$2:$C$232,"",0)
A101: =$A$89+B101 | B101: 12 | C101: =_xlfn.XLOOKUP(B101,Fastening!$E$78:$E$107,Fastening!$A$78:$A$107,"",0) | D101: =_xlfn.XLOOKUP(B101,Fastening!$E$78:$E$107,Fastening!$B$78:$B$107,"",0) | E101: {=_xlfn.XLOOKUP(B101,Fastening!$E$78:$E$107,_xlfn.ANCHORARRAY(Fastening!$C$78),"",0)} | F101: =_xlfn.XLOOKUP(C101,Articles!$A$2:$A$232,Articles!$C$2:$C$232,"",0)
... A116: =$A$89+B116 | B116: 27 | C116: =_xlfn.XLOOKUP(B116,Fastening!$E$78:$E$107,Fastening!$A$78:$A$107,"",0) | D116: =_xlfn.XLOOKUP(B116,Fastening!$E$78:$E$107,Fastening!$B$78:$B$107,"",0) | E116: {=_xlfn.XLOOKUP(B116,Fastening!$E$78:$E$107,_xlfn.ANCHORARRAY(Fastening!$C$78),"",0)} | F116: =_xlfn.XLOOKUP(C116,Articles!$A$2:$A$232,Articles!$C$2:$C$232,"",0)
A117: =$A$89+B117 | B117: 28 | C117: =_xlfn.XLOOKUP(B117,Fastening!$E$78:$E$107,Fastening!$A$78:$A$107,"",0) | D117: =_xlfn.XLOOKUP(B117,Fastening!$E$78:$E$107,Fastening!$B$78:$B$107,"",0) | E117: {=_xlfn.XLOOKUP(B117,Fastening!$E$78:$E$107,_xlfn.ANCHORARRAY(Fastening!$C$78),"",0)} | F117: =_xlfn.XLOOKUP(C117,Articles!$A$2:$A$232,Articles!$C$2:$C$232,"",0) | G117: PRICE/UNIT | H117: PRICE | I117: MONTAGE/UNIT | J117: MONTAGE
A118: =$A$89+B118 | B118: 29 | C118: =_xlfn.XLOOKUP(B118,Fastening!$E$78:$E$107,Fastening!$A$78:$A$107,"",0) | D118: =_xlfn.XLOOKUP(B118,Fastening!$E$78:$E$107,Fastening!$B$78:$B$107,"",0) | E118: {=_xlfn.XLOOKUP(B118,Fastening!$E$78:$E$107,_xlfn.ANCHORARRAY(Fastening!$C$78),"",0)} | F118: =_xlfn.XLOOKUP(C118,Articles!$A$2:$A$232,Articles!$C$2:$C$232,"",0) | G118: TOTAL | H118: =SUM(H119:H235) | I118: TOTAL | J118: =SUM(J119:J235)
A119: =B119*IF(Calc!$D$105="?",0,1) | B119: 1 | C119: =_xlfn.XLOOKUP($A119,$B$2:$B$89,C$2:C$89,"",0)&_xlfn.XLOOKUP($A119,$A$90:$A$118,C$90:C$118,"",0) | D119: =_xlfn.XLOOKUP($A119,$B$2:$B$89,D$2:D$89,"",0)&_xlfn.XLOOKUP($A119,$A$90:$A$118,D$90:D$118,"",0) | E119: =_xlfn.XLOOKUP($A119,$B$2:$B$89,E$2:E$89,"",0)&_xlfn.XLOOKUP($A119,$A$90:$A$118,E$90:E$118,"",0) | F119: =_xlfn.XLOOKUP($A119,$B$2:$B$89,F$2:F$89,"",0)&_xlfn.XLOOKUP($A119,$A$90:$A$118,F$90:F$118,"",0) | G119: =_xlfn.XLOOKUP(C119,Articles!A:A,Articles!D:D,0,0) | H119: =IF(E119<>"",E119*G119,0) | I119: =_xlfn.XLOOKUP(C119,Articles!A:A,Articles!E:E,0,0) | J119: =IF(E119<>"",I119*E119,0)
A120: =B120*IF(Calc!$D$105="?",0,1) | B120: 2 | C120: =_xlfn.XLOOKUP($A120,$B$2:$B$89,C$2:C$89,"",0)&_xlfn.XLOOKUP($A120,$A$90:$A$118,C$90:C$118,"",0) | D120: =_xlfn.XLOOKUP($A120,$B$2:$B$89,D$2:D$89,"",0)&_xlfn.XLOOKUP($A120,$A$90:$A$118,D$90:D$118,"",0) | E120: =_xlfn.XLOOKUP($A120,$B$2:$B$89,E$2:E$89,"",0)&_xlfn.XLOOKUP($A120,$A$90:$A$118,E$90:E$118,"",0) | F120: =_xlfn.XLOOKUP($A120,$B$2:$B$89,F$2:F$89,"",0)&_xlfn.XLOOKUP($A120,$A$90:$A$118,F$90:F$118,"",0) | G120: =_xlfn.XLOOKUP(C120,Articles!A:A,Articles!D:D,0,0) | H120: =IF(E120<>"",E120*G120,0) | I120: =_xlfn.XLOOKUP(C120,Articles!A:A,Articles!E:E,0,0) | J120: =IF(E120<>"",I120*E120,0)
A121: =B121*IF(Calc!$D$105="?",0,1) | B121: 3 | C121: =_xlfn.XLOOKUP($A121,$B$2:$B$89,C$2:C$89,"",0)&_xlfn.XLOOKUP($A121,$A$90:$A$118,C$90:C$118,"",0) | D121: =_xlfn.XLOOKUP($A121,$B$2:$B$89,D$2:D$89,"",0)&_xlfn.XLOOKUP($A121,$A$90:$A$118,D$90:D$118,"",0) | E121: =_xlfn.XLOOKUP($A121,$B$2:$B$89,E$2:E$89,"",0)&_xlfn.XLOOKUP($A121,$A$90:$A$118,E$90:E$118,"",0) | F121: =_xlfn.XLOOKUP($A121,$B$2:$B$89,F$2:F$89,"",0)&_xlfn.XLOOKUP($A121,$A$90:$A$118,F$90:F$118,"",0) | G121: =_xlfn.XLOOKUP(C121,Articles!A:A,Articles!D:D,0,0) | H121: =IF(E121<>"",E121*G121,0) | I121: =_xlfn.XLOOKUP(C121,Articles!A:A,Articles!E:E,0,0) | J121: =IF(E121<>"",I121*E121,0)
A122: =B122*IF(Calc!$D$105="?",0,1) | B122: 4 | C122: =_xlfn.XLOOKUP($A122,$B$2:$B$89,C$2:C$89,"",0)&_xlfn.XLOOKUP($A122,$A$90:$A$118,C$90:C$118,"",0) | D122: =_xlfn.XLOOKUP($A122,$B$2:$B$89,D$2:D$89,"",0)&_xlfn.XLOOKUP($A122,$A$90:$A$118,D$90:D$118,"",0) | E122: =_xlfn.XLOOKUP($A122,$B$2:$B$89,E$2:E$89,"",0)&_xlfn.XLOOKUP($A122,$A$90:$A$118,E$90:E$118,"",0) | F122: =_xlfn.XLOOKUP($A122,$B$2:$B$89,F$2:F$89,"",0)&_xlfn.XLOOKUP($A122,$A$90:$A$118,F$90:F$118,"",0) | G122: =_xlfn.XLOOKUP(C122,Articles!A:A,Articles!D:D,0,0) | H122: =IF(E122<>"",E122*G122,0) | I122: =_xlfn.XLOOKUP(C122,Articles!A:A,Articles!E:E,0,0) | J122: =IF(E122<>"",I122*E122,0)
A123: =B123*IF(Calc!$D$105="?",0,1) | B123: 5 | C123: =_xlfn.XLOOKUP($A123,$B$2:$B$89,C$2:C$89,"",0)&_xlfn.XLOOKUP($A123,$A$90:$A$118,C$90:C$118,"",0) | D123: =_xlfn.XLOOKUP($A123,$B$2:$B$89,D$2:D$89,"",0)&_xlfn.XLOOKUP($A123,$A$90:$A$118,D$90:D$118,"",0) | E123: =_xlfn.XLOOKUP($A123,$B$2:$B$89,E$2:E$89,"",0)&_xlfn.XLOOKUP($A123,$A$90:$A$118,E$90:E$118,"",0) | F123: =_xlfn.XLOOKUP($A123,$B$2:$B$89,F$2:F$89,"",0)&_xlfn.XLOOKUP($A123,$A$90:$A$118,F$90:F$118,"",0) | G123: =_xlfn.XLOOKUP(C123,Articles!A:A,Articles!D:D,0,0) | H123: =IF(E123<>"",E123*G123,0) | I123: =_xlfn.XLOOKUP(C123,Articles!A:A,Articles!E:E,0,0) | J123: =IF(E123<>"",I123*E123,0)
A124: =B124*IF(Calc!$D$105="?",0,1) | B124: 6 | C124: =_xlfn.XLOOKUP($A124,$B$2:$B$89,C$2:C$89,"",0)&_xlfn.XLOOKUP($A124,$A$90:$A$118,C$90:C$118,"",0) | D124: =_xlfn.XLOOKUP($A124,$B$2:$B$89,D$2:D$89,"",0)&_xlfn.XLOOKUP($A124,$A$90:$A$118,D$90:D$118,"",0) | E124: =_xlfn.XLOOKUP($A124,$B$2:$B$89,E$2:E$89,"",0)&_xlfn.XLOOKUP($A124,$A$90:$A$118,E$90:E$118,"",0) | F124: =_xlfn.XLOOKUP($A124,$B$2:$B$89,F$2:F$89,"",0)&_xlfn.XLOOKUP($A124,$A$90:$A$118,F$90:F$118,"",0) | G124: =_xlfn.XLOOKUP(C124,Articles!A:A,Articles!D:D,0,0) | H124: =IF(E124<>"",E124*G124,0) | I124: =_xlfn.XLOOKUP(C124,Articles!A:A,Articles!E:E,0,0) | J124: =IF(E124<>"",I124*E124,0)
A125: =B125*IF(Calc!$D$105="?",0,1) | B125: 7 | C125: =_xlfn.XLOOKUP($A125,$B$2:$B$89,C$2:C$89,"",0)&_xlfn.XLOOKUP($A125,$A$90:$A$118,C$90:C$118,"",0) | D125: =_xlfn.XLOOKUP($A125,$B$2:$B$89,D$2:D$89,"",0)&_xlfn.XLOOKUP($A125,$A$90:$A$118,D$90:D$118,"",0) | E125: =_xlfn.XLOOKUP($A125,$B$2:$B$89,E$2:E$89,"",0)&_xlfn.XLOOKUP($A125,$A$90:$A$118,E$90:E$118,"",0) | F125: =_xlfn.XLOOKUP($A125,$B$2:$B$89,F$2:F$89,"",0)&_xlfn.XLOOKUP($A125,$A$90:$A$118,F$90:F$118,"",0) | G125: =_xlfn.XLOOKUP(C125,Articles!A:A,Articles!D:D,0,0) | H125: =IF(E125<>"",E125*G125,0) | I125: =_xlfn.XLOOKUP(C125,Articles!A:A,Articles!E:E,0,0) | J125: =IF(E125<>"",I125*E125,0)
A126: =B126*IF(Calc!$D$105="?",0,1) | B126: 8 | C126: =_xlfn.XLOOKUP($A126,$B$2:$B$89,C$2:C$89,"",0)&_xlfn.XLOOKUP($A126,$A$90:$A$118,C$90:C$118,"",0) | D126: =_xlfn.XLOOKUP($A126,$B$2:$B$89,D$2:D$89,"",0)&_xlfn.XLOOKUP($A126,$A$90:$A$118,D$90:D$118,"",0) | E126: =_xlfn.XLOOKUP($A126,$B$2:$B$89,E$2:E$89,"",0)&_xlfn.XLOOKUP($A126,$A$90:$A$118,E$90:E$118,"",0) | F126: =_xlfn.XLOOKUP($A126,$B$2:$B$89,F$2:F$89,"",0)&_xlfn.XLOOKUP($A126,$A$90:$A$118,F$90:F$118,"",0) | G126: =_xlfn.XLOOKUP(C126,Articles!A:A,Articles!D:D,0,0) | H126: =IF(E126<>"",E126*G126,0) | I126: =_xlfn.XLOOKUP(C126,Articles!A:A,Articles!E:E,0,0) | J126: =IF(E126<>"",I126*E126,0)
A127: =B127*IF(Calc!$D$105="?",0,1) | B127: 9 | C127: =_xlfn.XLOOKUP($A127,$B$2:$B$89,C$2:C$89,"",0)&_xlfn.XLOOKUP($A127,$A$90:$A$118,C$90:C$118,"",0) | D127: =_xlfn.XLOOKUP($A127,$B$2:$B$89,D$2:D$89,"",0)&_xlfn.XLOOKUP($A127,$A$90:$A$118,D$90:D$118,"",0) | E127: =_xlfn.XLOOKUP($A127,$B$2:$B$89,E$2:E$89,"",0)&_xlfn.XLOOKUP($A127,$A$90:$A$118,E$90:E$118,"",0) | F127: =_xlfn.XLOOKUP($A127,$B$2:$B$89,F$2:F$89,"",0)&_xlfn.XLOOKUP($A127,$A$90:$A$118,F$90:F$118,"",0) | G127: =_xlfn.XLOOKUP(C127,Articles!A:A,Articles!D:D,0,0) | H127: =IF(E127<>"",E127*G127,0) | I127: =_xlfn.XLOOKUP(C127,Articles!A:A,Articles!E:E,0,0) | J127: =IF(E127<>"",I127*E127,0)
A128: =B128*IF(Calc!$D$105="?",0,1) | B128: 10 | C128: =_xlfn.XLOOKUP($A128,$B$2:$B$89,C$2:C$89,"",0)&_xlfn.XLOOKUP($A128,$A$90:$A$118,C$90:C$118,"",0) | D128: =_xlfn.XLOOKUP($A128,$B$2:$B$89,D$2:D$89,"",0)&_xlfn.XLOOKUP($A128,$A$90:$A$118,D$90:D$118,"",0) | E128: =_xlfn.XLOOKUP($A128,$B$2:$B$89,E$2:E$89,"",0)&_xlfn.XLOOKUP($A128,$A$90:$A$118,E$90:E$118,"",0) | F128: =_xlfn.XLOOKUP($A128,$B$2:$B$89,F$2:F$89,"",0)&_xlfn.XLOOKUP($A128,$A$90:$A$118,F$90:F$118,"",0) | G128: =_xlfn.XLOOKUP(C128,Articles!A:A,Articles!D:D,0,0) | H128: =IF(E128<>"",E128*G128,0) | I128: =_xlfn.XLOOKUP(C128,Articles!A:A,Articles!E:E,0,0) | J128: =IF(E128<>"",I128*E128,0)
...

Sheet Language
A1: LALIST | B1: Nederlands | C1: Français | D1: English | E1: Selected
B2: ="Overkapping 'Domino"&IF(Calc!$D$18=1," PLUS","")&"' - BxL="&Configure!$G$15 | C2: ="Auvent 'Domino"&IF(Calc!$D$18=1," PLUS","")&"' - LxL="&Configure!$G$15 | D2: ="Shelter 'Domino"&IF(Calc!$D$18=1," PLUS","")&"' - WxL="&Configure!$G$15 | E2: =_xlfn.XLOOKUP('PRC import'!$H$3,LALIST,Language!B2:D2)
B3: Oppervlaktebehandeling - verzinkt | C3: Traitement de surface - galvanisé | D3: Surface treatment - galvanized | E3: =_xlfn.XLOOKUP('PRC import'!$H$3,LALIST,Language!B3:D3)
B4: Oppervlaktebehandeling - verzinkt en gepoedercoat | C4: Traitement de surface - galvanisé et thermolaqué | D4: Surface treatment - galvanized and powder coated | E4: =_xlfn.XLOOKUP('PRC import'!$H$3,LALIST,Language!B4:D4)
B5: Oppervlaktebehandeling - verzinkt - enkel dakrand gepoedercoat | C5: Traitement de surface - galvanisé - juste bord de toit thermolaqué | D5: Surface treatment - galvanized - only roof edge powder coated | E5: =_xlfn.XLOOKUP('PRC import'!$H$3,LALIST,Language!B5:D5)
B6: Dakbedekking in geprofileerde staalplaat (onderzijde gebroken wit - bovenzijde RAL7016) | C6: Toiture en tôle d'acier profilée (intérieur blanc cassé - extérieur RAL7016) | D6: Roof in profiled steel sheet (bottom off-white - top RAL7016) | E6: =_xlfn.XLOOKUP('PRC import'!$H$3,LALIST,Language!B6:D6)
B7: Dakbedekking in geprofileerd massief polycarbonaat (helder) | C7: Toiture en polycarbonate solide profilé (transparent) | D7: Roof in profiled solid polycarbonate (clear) | E7: =_xlfn.XLOOKUP('PRC import'!$H$3,LALIST,Language!B7:D7)
B8: {="Wandbekleding in Nylofor-2D ("&_xlfn.SWITCH(Calc!D38, 1, "RAL6005", 2, "RAL7016", 3, "RAL9005", 4, "verzinkt", "")&") - H="&2.03+Calc!D18*0.65&"m"&IF((Calc!D40+Calc!D42)>0," - "&(Calc!D40+Calc!D42)&"x L="&Calc!D9&"m","")&IF((Calc!D39+Calc!D41)>0," - "&(Calc!D39+Calc!D41)&"x L="&Calc!D10&"m","")} | C8: {="Parois en Nylofor-2D ("&_xlfn.SWITCH(Calc!D38, 1, "RAL6005", 2, "RAL7016", 3, "RAL9005", 4, "galvanisé", "")&") - H="&2.03+Calc!D18*0.65&"m"&IF((Calc!D40+Calc!D42)>0," - "&(Calc!D40+Calc!D42)&"x L="&Calc!D9&"m","")&IF((Calc!D39+Calc!D41)>0," - "&(Calc!D39+Calc!D41)&"x L="&Calc!D10&"m","")} | D8: {="Wall cladding in Nylofor-2D ("&_xlfn.SWITCH(Calc!D38, 1, "RAL6005", 2, "RAL7016", 3, "RAL9005", 4, "galvanized", "")&") - H="&2.03+Calc!D18*0.65&"m"&IF((Calc!D40+Calc!D42)>0," - "&(Calc!D40+Calc!D42)&"x L="&Calc!D9&"m","")&IF((Calc!D39+Calc!D41)>0," - "&(Calc!D39+Calc!D41)&"x L="&Calc!D10&"m","")} | E8: =_xlfn.XLOOKUP('PRC import'!$H$3,LALIST,Language!B8:D8)
B9: ="Wandbekleding in Thermowood - H="&2.15+Calc!D18*0.65&"m"&IF((Calc!D40+Calc!D42)>0," - "&(Calc!D40+Calc!D42)&"x L="&Calc!D9&"m","")&IF((Calc!D39+Calc!D41)>0," - "&(Calc!D39+Calc!D41)&"x L="&Calc!D10&"m","") | C9: ="Parois en Thermowood - H="&2.15+Calc!D18*0.65&"m"&IF((Calc!D40+Calc!D42)>0," - "&(Calc!D40+Calc!D42)&"x L="&Calc!D9&"m","")&IF((Calc!D39+Calc!D41)>0," - "&(Calc!D39+Calc!D41)&"x L="&Calc!D10&"m","") | D9: ="Wall cladding in Thermowood - H="&2.15+Calc!D18*0.65&"m"&IF((Calc!D40+Calc!D42)>0," - "&(Calc!D40+Calc!D42)&"x L="&Calc!D9&"m","")&IF((Calc!D39+Calc!D41)>0," - "&(Calc!D39+Calc!D41)&"x L="&Calc!D10&"m","") | E9: =_xlfn.XLOOKUP('PRC import'!$H$3,LALIST,Language!B9:D9)
B10: ="Wandbekleding in gehard glas - H="&2.15+Calc!D18*0.65&"m"&IF((Calc!D40+Calc!D42)>0," - "&(Calc!D40+Calc!D42)&"x L="&Calc!D9&"m","")&IF((Calc!D39+Calc!D41)>0," - "&(Calc!D39+Calc!D41)&"x L="&Calc!D10&"m","") | C10: ="Parois en verre trempé - H="&2.15+Calc!D18*0.65&"m"&IF((Calc!D40+Calc!D42)>0," - "&(Calc!D40+Calc!D42)&"x L="&Calc!D9&"m","")&IF((Calc!D39+Calc!D41)>0," - "&(Calc!D39+Calc!D41)&"x L="&Calc!D10&"m","") | D10: ="Wall cladding in tempered glass - H="&2.15+Calc!D18*0.65&"m"&IF((Calc!D40+Calc!D42)>0," - "&(Calc!D40+Calc!D42)&"x L="&Calc!D9&"m","")&IF((Calc!D39+Calc!D41)>0," - "&(Calc!D39+Calc!D41)&"x L="&Calc!D10&"m","") | E10: =_xlfn.XLOOKUP('PRC import'!$H$3,LALIST,Language!B10:D10)
B11: ="Ingang - " & _xlfn.TEXTJOIN(" - ", TRUE, IF(Calc!D50>0, Calc!D50 & "x wandopening 2,03m", ""), IF(Calc!D51>0, Calc!D51 & "x wandopening 2,53m", ""), IF(Calc!D52>0, Calc!D52 & "x enkele draaipoort 2,03m", ""), IF(Calc!D53>0, Calc!D53 & "x enkele draaipoort 2,53m", ""), IF(Calc!D54>0, Calc!D54 & "x dubbele draaipoort 2,03m", ""), IF(Calc!D55>0, Calc!D55 & "x dubbele draaipoort 2,53m", "") ) | C11: ="Entrée - " & _xlfn.TEXTJOIN(" - ", TRUE, IF(Calc!D50>0, Calc!D50 & "x ouverture murale 2,03m", ""), IF(Calc!D51>0, Calc!D51 & "x ouverture murale 2,53m", ""), IF(Calc!D52>0, Calc!D52 & "x portail battant simple 2,03m", ""), IF(Calc!D53>0, Calc!D53 & "x portail battant simple 2,53m", ""), IF(Calc!D54>0, Calc!D54 & "x portail battant double 2,03m", ""), IF(Calc!D55>0, Calc!D55 & "x portail battant double 2,53m", "") ) | D11: ="Entrance - " & _xlfn.TEXTJOIN(" - ", TRUE, IF(Calc!D50>0, Calc!D50 & "x wall opening 2,03m", ""), IF(Calc!D51>0, Calc!D51 & "x wall opening 2,53m", ""), IF(Calc!D52>0, Calc!D52 & "x single swing gate 2,03m", ""), IF(Calc!D53>0, Calc!D53 & "x single swing gate 2,53m", ""), IF(Calc!D54>0, Calc!D54 & "x double swing gate 2,03m", ""), IF(Calc!D55>0, Calc!D55 & "x double swing gate 2,53m", "") ) | E11: =_xlfn.XLOOKUP('PRC import'!$H$3,LALIST,Language!B11:D11)
B12: {="Zonder "&_xlfn.SWITCH(Calc!D37,1,"Nylofor 2D",2,"Thermowood",3,"glas","")&" - kolommen / gordingen blijven"} | C12: {="Sans "&_xlfn.SWITCH(Calc!D37,1,"Nylofor 2D",2,"Thermowood",3,"verre","")&" - colonnes / montants restent"} | D12: {="Without "&_xlfn.SWITCH(Calc!D37,1,"Nylofor 2D",2,"Thermowood",3,"glass","")&" - columns / girders remain"} | E12: =_xlfn.XLOOKUP('PRC import'!$H$3,LALIST,Language!B12:D12)
B13: Met poortbeslag - eurocilinderslot | C13: Avec accessoires de portail - serrure à cylindre européen | D13: With gate hardware - euro cylinder lock | E13: =_xlfn.XLOOKUP('PRC import'!$H$3,LALIST,Language!B13:D13)
B14: Met poortbeslag - mechanisch codeslot - dubbelzijdig | C14: Avec accessoires de portail - serrure à code mécanique - double face | D14: With gate hardware - mechanical code lock - double sided | E14: =_xlfn.XLOOKUP('PRC import'!$H$3,LALIST,Language!B14:D14)
B15: Met poortbeslag - batterijgevoed codeslot - dubbelzijdig | C15: Avec accessoires de portail - serrure à code sur batterie - double face | D15: With gate hardware - battery powered code lock - double sided | E15: =_xlfn.XLOOKUP('PRC import'!$H$3,LALIST,Language!B15:D15)
B16: Zonder poortbeslag (slotkast - slotvanger - krukpaar - grondgrendel - cilinder) | C16: Sans accessoires de portail (serrure - gâche - poignées - verrou de sol - cylindre) | D16: Without gate hardware (lock - keep - handles - drop bolt - cylinder) | E16: =_xlfn.XLOOKUP('PRC import'!$H$3,LALIST,Language!B16:D16)
B17: ="LED verlichting - "&Calc!D26*Calc!D29&" "&IF(Calc!D26*Calc!D29>1,"armaturen","armatuur")&" - bekabeling in opbouw" | C17: ="Eclairage LED - "&Calc!D26*Calc!D29&" "&IF(Calc!D26*Calc!D29>1,"luminaires","luminaire")&" - câbles en apparent" | D17: ="LED lighting - "&Calc!D26*Calc!D29&" "&IF(Calc!D26*Calc!D29>1,"fixtures","fixture")&" - surface-mounted wiring" | E17: =_xlfn.XLOOKUP('PRC import'!$H$3,LALIST,Language!B17:D17)
B18: ="Dakrand - aluminium L-profiel - H=80mm"&IF(Calc!D15=1," - gepoedercoat","") | C18: ="Bordure de toit - cornière en aluminium - H=80mm"&IF(Calc!D15=1," - thermolaqué","") | D18: ="Roof edge trim - aluminium L-profile - H=80mm"&IF(Calc!D15=1," - powder coated","") | E18: =_xlfn.XLOOKUP('PRC import'!$H$3,LALIST,Language!B18:D18)
B19: Chemische verankering - ETA-21/0168 | C19: Ancrage chimique - ETA-21/0168 | D19: Chemical anchoring - ETA-21/0168 | E19: =_xlfn.XLOOKUP('PRC import'!$H$3,LALIST,Language!B19:D19)
B20: =IF(Calc!D67=1,"Inclusief ","Exclusief ")&"montage en transport" | C20: ="Montage et transport"&IF(Calc!D67=1," inclus"," exclus") | D20: ="Installation and transport"&IF(Calc!D67=1," included"," excluded") | E20: =_xlfn.XLOOKUP('PRC import'!$H$3,LALIST,Language!B20:D20)
B21: Exclusief funderingen | C21: Fondations exclus | D21: Foundations excluded | E21: =_xlfn.XLOOKUP('PRC import'!$H$3,LALIST,Language!B21:D21)

Sheet Articles
A1: CODE | B1: DESCR | C1: UNIT | D1: PRICE (EUR) | E1: MONTAGE (HRS)
A2: 43.13.07.0011 | B2: Domino - Beam - 120x60x3 - L1890 - 8Ø13 - Galvanized | C2: st | D2: =_xlfn.XLOOKUP(A2,Price!A:A,Price!C:C,0,0) | E2: =_xlfn.XLOOKUP(A2,Montage!A:A,Montage!C:C,0,0)+IF(Calc!$D$18=1,_xlfn.XLOOKUP(A2,Montage!A:A,Montage!D:D,0,0),0)
A3: 43.13.07.0013 | B3: Domino - Beam - 120x60x3 - L1890 - 8Ø13 - Powder Coated | C3: st | D3: =_xlfn.XLOOKUP(A3,Price!A:A,Price!C:C,0,0) | E3: =_xlfn.XLOOKUP(A3,Montage!A:A,Montage!C:C,0,0)+IF(Calc!$D$18=1,_xlfn.XLOOKUP(A3,Montage!A:A,Montage!D:D,0,0),0)
A4: 43.13.07.0004 | B4: Domino - Beam - 120x60x3 - L2098 - 2Ø13 - Galvanized | C4: st | D4: =_xlfn.XLOOKUP(A4,Price!A:A,Price!C:C,0,0) | E4: =_xlfn.XLOOKUP(A4,Montage!A:A,Montage!C:C,0,0)+IF(Calc!$D$18=1,_xlfn.XLOOKUP(A4,Montage!A:A,Montage!D:D,0,0),0)
A5: 43.13.07.0008 | B5: Domino - Beam - 120x60x3 - L2098 - 2Ø13 - Powder Coated | C5: st | D5: =_xlfn.XLOOKUP(A5,Price!A:A,Price!C:C,0,0) | E5: =_xlfn.XLOOKUP(A5,Montage!A:A,Montage!C:C,0,0)+IF(Calc!$D$18=1,_xlfn.XLOOKUP(A5,Montage!A:A,Montage!D:D,0,0),0)
A6: 43.13.07.0012 | B6: Domino - Beam - 120x60x3 - L2390 - 8Ø13 - Galvanized | C6: st | D6: =_xlfn.XLOOKUP(A6,Price!A:A,Price!C:C,0,0) | E6: =_xlfn.XLOOKUP(A6,Montage!A:A,Montage!C:C,0,0)+IF(Calc!$D$18=1,_xlfn.XLOOKUP(A6,Montage!A:A,Montage!D:D,0,0),0)
A7: 43.13.07.0014 | B7: Domino - Beam - 120x60x3 - L2390 - 8Ø13 - Powder Coated | C7: st | D7: =_xlfn.XLOOKUP(A7,Price!A:A,Price!C:C,0,0) | E7: =_xlfn.XLOOKUP(A7,Montage!A:A,Montage!C:C,0,0)+IF(Calc!$D$18=1,_xlfn.XLOOKUP(A7,Montage!A:A,Montage!D:D,0,0),0)
A8: 43.13.07.0015 | B8: Domino - Beam - 120x60x3 - L2598 - 2Ø13 - Galvanized | C8: st | D8: =_xlfn.XLOOKUP(A8,Price!A:A,Price!C:C,0,0) | E8: =_xlfn.XLOOKUP(A8,Montage!A:A,Montage!C:C,0,0)+IF(Calc!$D$18=1,_xlfn.XLOOKUP(A8,Montage!A:A,Montage!D:D,0,0),0)
A9: 43.13.07.0016 | B9: Domino - Beam - 120x60x3 - L2598 - 2Ø13 - Powder Coated | C9: st | D9: =_xlfn.XLOOKUP(A9,Price!A:A,Price!C:C,0,0) | E9: =_xlfn.XLOOKUP(A9,Montage!A:A,Montage!C:C,0,0)+IF(Calc!$D$18=1,_xlfn.XLOOKUP(A9,Montage!A:A,Montage!D:D,0,0),0)
A10: 43.13.07.0001 | B10: Domino - Beam - 120x60x3 - L3920 - 8Ø13 - Galvanized | C10: st | D10: =_xlfn.XLOOKUP(A10,Price!A:A,Price!C:C,0,0) | E10: =_xlfn.XLOOKUP(A10,Montage!A:A,Montage!C:C,0,0)+IF(Calc!$D$18=1,_xlfn.XLOOKUP(A10,Montage!A:A,Montage!D:D,0,0),0)
A11: 43.13.07.0005 | B11: Domino - Beam - 120x60x3 - L3920 - 8Ø13 - Powder Coated | C11: st | D11: =_xlfn.XLOOKUP(A11,Price!A:A,Price!C:C,0,0) | E11: =_xlfn.XLOOKUP(A11,Montage!A:A,Montage!C:C,0,0)+IF(Calc!$D$18=1,_xlfn.XLOOKUP(A11,Montage!A:A,Montage!D:D,0,0),0)
A12: 43.13.07.0002 | B12: Domino - Beam - 120x60x3 - L4920 - 8Ø13 - Galvanized | C12: st | D12: =_xlfn.XLOOKUP(A12,Price!A:A,Price!C:C,0,0) | E12: =_xlfn.XLOOKUP(A12,Montage!A:A,Montage!C:C,0,0)+IF(Calc!$D$18=1,_xlfn.XLOOKUP(A12,Montage!A:A,Montage!D:D,0,0),0)
A13: 43.13.07.0006 | B13: Domino - Beam - 120x60x3 - L4920 - 8Ø13 - Powder Coated | C13: st | D13: =_xlfn.XLOOKUP(A13,Price!A:A,Price!C:C,0,0) | E13: =_xlfn.XLOOKUP(A13,Montage!A:A,Montage!C:C,0,0)+IF(Calc!$D$18=1,_xlfn.XLOOKUP(A13,Montage!A:A,Montage!D:D,0,0),0)
... A232: 18.03.03.0001 | B232: Chemical anchor - capsule M12x95 - Würth W-VPZ 12 | C232: st | D232: =_xlfn.XLOOKUP(A232,Price!A:A,Price!C:C,0,0) | E232: =_xlfn.XLOOKUP(A232,Montage!A:A,Montage!C:C,0,0)+IF(Calc!$D$18=1,_xlfn.XLOOKUP(A232,Montage!A:A,Montage!D:D,0,0),0)

Sheet Price
A1: CODE | B1: DESCR | C1: PRICE (EUR)
A2: 43.13.07.0011 | B2: Domino - Beam - 120x60x3 - L1890 - 8Ø13 - Galvanized | C2: 83.88
A3: 43.13.07.0013 | B3: Domino - Beam - 120x60x3 - L1890 - 8Ø13 - Powder Coated | C3: 127.27
A4: 43.13.07.0004 | B4: Domino - Beam - 120x60x3 - L2098 - 2Ø13 - Galvanized | C4: 98.35
A5: 43.13.07.0008 | B5: Domino - Beam - 120x60x3 - L2098 - 2Ø13 - Powder Coated | C5: 146.36
A6: 43.13.07.0012 | B6: Domino - Beam - 120x60x3 - L2390 - 8Ø13 - Galvanized | C6: 100.12
A7: 43.13.07.0014 | B7: Domino - Beam - 120x60x3 - L2390 - 8Ø13 - Powder Coated | C7: 155.62
A8: 43.13.07.0015 | B8: Domino - Beam - 120x60x3 - L2598 - 2Ø13 - Galvanized | C8: 164.58
A9: 43.13.07.0016 | B9: Domino - Beam - 120x60x3 - L2598 - 2Ø13 - Powder Coated | C9: 225.07
A10: 43.13.07.0001 | B10: Domino - Beam - 120x60x3 - L3920 - 8Ø13 - Galvanized | C10: 194.69
A11: 43.13.07.0005 | B11: Domino - Beam - 120x60x3 - L3920 - 8Ø13 - Powder Coated | C11: 281.26
A12: 43.13.07.0002 | B12: Domino - Beam - 120x60x3 - L4920 - 8Ø13 - Galvanized | C12: 209.17
A13: 43.13.07.0006 | B13: Domino - Beam - 120x60x3 - L4920 - 8Ø13 - Powder Coated | C13: 318.49
... A220: 20.10.02.0039 | B220: Euro Cylinder with 3 keys - 50/70mm | C220: 102.62

Sheet Montage
A1: CODE | B1: DESCR | C1: MONTAGE (HRS) | D1: EXTRA PLUS (HRS)
A2: 43.13.07.0011 | B2: Domino - Beam - 120x60x3 - L1890 - 8Ø13 - Galvanized | C2: 0.2 | D2: 0.1
A3: 43.13.07.0013 | B3: Domino - Beam - 120x60x3 - L1890 - 8Ø13 - Powder Coated | C3: 0.2 | D3: 0.1
A4: 43.13.07.0004 | B4: Domino - Beam - 120x60x3 - L2098 - 2Ø13 - Galvanized | C4: 0.2 | D4: 0.1
A5: 43.13.07.0008 | B5: Domino - Beam - 120x60x3 - L2098 - 2Ø13 - Powder Coated | C5: 0.2 | D5: 0.1
A6: 43.13.07.0012 | B6: Domino - Beam - 120x60x3 - L2390 - 8Ø13 - Galvanized | C6: 0.2 | D6: 0.1
A7: 43.13.07.0014 | B7: Domino - Beam - 120x60x3 - L2390 - 8Ø13 - Powder Coated | C7: 0.2 | D7: 0.1
A8: 43.13.07.0015 | B8: Domino - Beam - 120x60x3 - L2598 - 2Ø13 - Galvanized | C8: 0.2 | D8: 0.1
A9: 43.13.07.0016 | B9: Domino - Beam - 120x60x3 - L2598 - 2Ø13 - Powder Coated | C9: 0.2 | D9: 0.1
A10: 43.13.07.0001 | B10: Domino - Beam - 120x60x3 - L3920 - 8Ø13 - Galvanized | C10: 0.27 | D10: 0.1
A11: 43.13.07.0005 | B11: Domino - Beam - 120x60x3 - L3920 - 8Ø13 - Powder Coated | C11: 0.27 | D11: 0.1
A12: 43.13.07.0002 | B12: Domino - Beam - 120x60x3 - L4920 - 8Ø13 - Galvanized | C12: 0.27 | D12: 0.1
A13: 43.13.07.0006 | B13: Domino - Beam - 120x60x3 - L4920 - 8Ø13 - Powder Coated | C13: 0.27 | D13: 0.1
... A15: 43.13.07.0007 | B15: Domino - Beam - 120x60x3 - L5950 - 8Ø13 - Powder Coated | C15: 0.27 | D15: 0.1
A16: 43.09.06.0015 | B16: Domino - Beam Connector - Bracket - Galvanized
A17: 43.09.06.0016 | B17: Domino - Beam Connector - Bracket - Powder Coated
A18: 43.09.06.0011 | B18: Domino - Beam Connector - L-Profile - Galvanized
A19: 43.09.06.0013 | B19: Domino - Beam Connector - L-Profile - Powder Coated
A20: 43.07.18.0009 | B20: Domino - Brace - 50x2 - L3065 - Galvanized | C20: 0.4
A21: 43.07.18.0011 | B21: Domino - Brace - 50x2 - L3065 - Powder Coated | C21: 0.4
A22: 43.07.18.0010 | B22: Domino - Brace - 50x2 - L3399 - Galvanized | C22: 0.4
A23: 43.07.18.0012 | B23: Domino - Brace - 50x2 - L3399 - Powder Coated | C23: 0.4
A24: 43.07.18.0015 | B24: Domino - Brace - Flat 50x5 - L2262 - Galvanized | C24: 0.2
A25: 43.07.18.0016 | B25: Domino - Brace - Flat 50x5 - L2699 - Galvanized | C25: 0.2
A26: 43.07.18.0017 | B26: Domino - Brace - Flat 50x5 - L2262 - Powder Coated | C26: 0.2
A27: 43.07.18.0018 | B27: Domino - Brace - Flat 50x5 - L2699 - Powder Coated | C27: 0.2
A28: 43.09.06.0017 | B28: Domino - Brace Connector - Galvanized
A29: 43.09.06.0018 | B29: Domino - Brace Connector - Powder Coated
A30: 43.06.14.0043 | B30: Domino - Column - 80x3 - L2175 - 8Ø13 - 8Ø9 - Galvanized | C30: 0.87
A31: 43.06.14.0047 | B31: Domino - Column - 80x3 - L2175 - 8Ø13 - 8Ø9 - Powder Coated | C31: 0.87
A32: 43.06.14.0041 | B32: Domino - Column - 80x3 - L2175 - 8Ø13 - Galvanized | C32: 0.87
A33: 43.06.14.0045 | B33: Domino - Column - 80x3 - L2175 - 8Ø13 - Powder Coated | C33: 0.87
A34: 43.06.14.0044 | B34: Domino - Column - 80x3 - L2825 - 8Ø13 - 16Ø9 - Galvanized | C34: 0.87
A35: 43.06.14.0048 | B35: Domino - Column - 80x3 - L2825 - 8Ø13 - 16Ø9 - Powder Coated | C35: 0.87
A36: 43.06.14.0042 | B36: Domino - Column - 80x3 - L2825 - 8Ø13 - Galvanized | C36: 0.87
A37: 43.06.14.0046 | B37: Domino - Column - 80x3 - L2825 - 8Ø13 - Powder Coated | C37: 0.87
A38: 43.03.10.0002 | B38: Domino - Foot - 70x4 - L605 - Galvanized
A39: 43.03.10.0001 | B39: Domino - Foot - 70x4 - L605 - Outflow - Galvanized
A40: 43.03.10.0004 | B40: Domino - Foot - 70x4 - L605 - Outflow - Powder Coated
A41: 43.03.10.0005 | B41: Domino - Foot - 70x4 - L605 - Powder Coated
...
